Traceback (most recent call last):
  File "C:\Users\vanlance\AppData\Local\Programs\Python\Python35\lib\urllib\request.py", line 1254, in do_open
    h.request(req.get_method(), req.selector, req.data, headers)
  File "C:\Users\vanlance\AppData\Local\Programs\Python\Python35\lib\http\client.py", line 1106, in request
    self._send_request(method, url, body, headers)
  File "C:\Users\vanlance\AppData\Local\Programs\Python\Python35\lib\http\client.py", line 1151, in _send_request
    self.endheaders(body)
  File "C:\Users\vanlance\AppData\Local\Programs\Python\Python35\lib\http\client.py", line 1102, in endheaders
    self._send_output(message_body)
  File "C:\Users\vanlance\AppData\Local\Programs\Python\Python35\lib\http\client.py", line 934, in _send_output
    self.send(msg)
  File "C:\Users\vanlance\AppData\Local\Programs\Python\Python35\lib\http\client.py", line 877, in send
    self.connect()
  File "C:\Users\vanlance\AppData\Local\Programs\Python\Python35\lib\http\client.py", line 849, in connect
    (self.host,self.port), self.timeout, self.source_address)
  File "C:\Users\vanlance\AppData\Local\Programs\Python\Python35\lib\socket.py", line 693, in create_connection
    for res in getaddrinfo(host, port, 0, SOCK_STREAM):
  File "C:\Users\vanlance\AppData\Local\Programs\Python\Python35\lib\socket.py", line 732, in getaddrinfo
    for res in _socket.getaddrinfo(host, port, family, type, proto, flags):
socket.gaierror: [Errno 11001] getaddrinfo failed

During handling of the above exception, another exception occurred:

Traceback (most recent call last):
  File "F:\mygit\python\exchange_dj\index\api\api.py", line 49, in inn
    data = fun(*args,**kw)
  File "F:\mygit\python\exchange_dj\index\api\zb\zb_api.py", line 165, in depth
    obj = self.__api_public_call(method, params)
  File "F:\mygit\python\exchange_dj\index\api\zb\zb_api.py", line 81, in __api_public_call
    res = urllib.request.urlopen(req, timeout=10)
  File "C:\Users\vanlance\AppData\Local\Programs\Python\Python35\lib\urllib\request.py", line 163, in urlopen
    return opener.open(url, data, timeout)
  File "C:\Users\vanlance\AppData\Local\Programs\Python\Python35\lib\urllib\request.py", line 466, in open
    response = self._open(req, data)
  File "C:\Users\vanlance\AppData\Local\Programs\Python\Python35\lib\urllib\request.py", line 484, in _open
    '_open', req)
  File "C:\Users\vanlance\AppData\Local\Programs\Python\Python35\lib\urllib\request.py", line 444, in _call_chain
    result = func(*args)
  File "C:\Users\vanlance\AppData\Local\Programs\Python\Python35\lib\urllib\request.py", line 1282, in http_open
    return self.do_open(http.client.HTTPConnection, req)
  File "C:\Users\vanlance\AppData\Local\Programs\Python\Python35\lib\urllib\request.py", line 1256, in do_open
    raise URLError(err)
urllib.error.URLError: <urlopen error [Errno 11001] getaddrinfo failed>
